Workbook

Sheet Simulador
B2: Precio del Inmueble | C2: 377500
B3: Inicial % | C3: =C4/C2 -> 0.42384106
B4: Cuota Inicial | C4: 160000
B5: Importe del Prestamo | C5: =C2-C4 -> 217500
B6: TEA | C6: 0.0803
B7: TEM | C7: =(1+C6)^(1/12)-1 -> 0.0064573242
B8: Plazo Meses | C8: 240
B9: Seguro Desgravamen TEM | C9: 0.00028
B10: Seguro Inmueble TNA | C10: 0.0034
B11: Cuota Base | C11: =PMT(C7,C8,-C5) -> 1785.4006
B12: Cuota Mensual Extraordinaria | C12: =C11 + (C5*C9) + (C2*C10/12)+C13 -> 1953.259
B13: Aporte Extra Capital

Sheet Amortizacion
A1: Mes | B1: Saldo Inicial | C1: Cuota Base | D1: Interes | E1: Capital | F1: Aporte Extra | G1: Capital Total | H1: Saldo Final
A2: 1 | B2: =Simulador!C5 -> 217500 | C2: =Simulador!C11 -> 1785.4006 | D2: =B2*Simulador!C7 -> 1404.468 | E2: =C2-D2 -> 380.93262 | F2: 2000 | G2: =E2+F2 -> 2380.9326 | H2: =B2-G2 -> 215119.07
A3: 2 | B3: =H2 -> 215119.07 | C3: =Simulador!C11 -> 1785.4006 | D3: =B3*Simulador!C7 -> 1389.0936 | E3: =C3-D3 -> 396.30707 | F3: 2000 | G3: =E3+F3 -> 2396.3071 | H3: =B3-G3 -> 212722.76
A4: 3 | B4: =H3 -> 212722.76 | C4: =Simulador!C11 -> 1785.4006 | D4: =B4*Simulador!C7 -> 1373.6198 | E4: =C4-D4 -> 411.78081 | F4: 2000 | G4: =E4+F4 -> 2411.7808 | H4: =B4-G4 -> 210310.98
A5: 4 | B5: =H4 -> 210310.98 | C5: =Simulador!C11 -> 1785.4006 | D5: =B5*Simulador!C7 -> 1358.0462 | E5: =C5-D5 -> 427.35446 | F5: 2000 | G5: =E5+F5 -> 2427.3545 | H5: =B5-G5 -> 207883.63
A6: 5 | B6: =H5 -> 207883.63 | C6: =Simulador!C11 -> 1785.4006 | D6: =B6*Simulador!C7 -> 1342.372 | E6: =C6-D6 -> 443.02867 | F6: 2000 | G6: =E6+F6 -> 2443.0287 | H6: =B6-G6 -> 205440.6
A7: 6 | B7: =H6 -> 205440.6 | C7: =Simulador!C11 -> 1785.4006 | D7: =B7*Simulador!C7 -> 1326.5965 | E7: =C7-D7 -> 458.8041 | F7: 2000 | G7: =E7+F7 -> 2458.8041 | H7: =B7-G7 -> 202981.79
A8: 7 | B8: =H7 -> 202981.79 | C8: =Simulador!C11 -> 1785.4006 | D8: =B8*Simulador!C7 -> 1310.7192 | E8: =C8-D8 -> 474.6814 | F8: 2000 | G8: =E8+F8 -> 2474.6814 | H8: =B8-G8 -> 200507.11 | K8: =SUM(C2:C79) -> 139261.25
A9: 8 | B9: =H8 -> 200507.11 | C9: =Simulador!C11 -> 1785.4006 | D9: =B9*Simulador!C7 -> 1294.7394 | E9: =C9-D9 -> 490.66122 | F9: 2000 | G9: =E9+F9 -> 2490.6612 | H9: =B9-G9 -> 198016.45 | K9: =SUM(F2:F65) -> 128000 | L9: =SUM(C2:C60) -> 105338.64
A10: 9 | B10: =H9 -> 198016.45 | C10: =Simulador!C11 -> 1785.4006 | D10: =B10*Simulador!C7 -> 1278.6564 | E10: =C10-D10 -> 506.74422 | F10: 2000 | G10: =E10+F10 -> 2506.7442 | H10: =B10-G10 -> 195509.71 | K10: =K8+K9 -> 267261.25
A11: 10 | B11: =H10 -> 195509.71 | C11: =Simulador!C11 -> 1785.4006 | D11: =B11*Simulador!C7 -> 1262.4696 | E11: =C11-D11 -> 522.93108 | F11: 2000 | G11: =E11+F11 -> 2522.9311 | H11: =B11-G11 -> 192986.77
A12: 11 | B12: =H11 -> 192986.77 | C12: =Simulador!C11 -> 1785.4006 | D12: =B12*Simulador!C7 -> 1246.1782 | E12: =C12-D12 -> 539.22247 | F12: 2000 | G12: =E12+F12 -> 2539.2225 | H12: =B12-G12 -> 190447.55
A13: 12 | B13: =H12 -> 190447.55 | C13: =Simulador!C11 -> 1785.4006 | D13: =B13*Simulador!C7 -> 1229.7816 | E13: =C13-D13 -> 555.61905 | F13: 2000 | G13: =E13+F13 -> 2555.619 | H13: =B13-G13 -> 187891.93 | K13: =314/80 -> 3.925
A14: 13 | B14: =H13 -> 187891.93 | C14: =Simulador!C11 -> 1785.4006 | D14: =B14*Simulador!C7 -> 1213.2791 | E14: =C14-D14 -> 572.12151 | F14: 2000 | G14: =E14+F14 -> 2572.1215 | H14: =B14-G14 -> 185319.81
A15: 14 | B15: =H14 -> 185319.81 | C15: =Simulador!C11 -> 1785.4006 | D15: =B15*Simulador!C7 -> 1196.6701 | E15: =C15-D15 -> 588.73053 | F15: 2000 | G15: =E15+F15 -> 2588.7305 | H15: =B15-G15 -> 182731.08
A16: 15 | B16: =H15 -> 182731.08 | C16: =Simulador!C11 -> 1785.4006 | D16: =B16*Simulador!C7 -> 1179.9538 | E16: =C16-D16 -> 605.4468 | F16: 2000 | G16: =E16+F16 -> 2605.4468 | H16: =B16-G16 -> 180125.63
A17: 16 | B17: =H16 -> 180125.63 | C17: =Simulador!C11 -> 1785.4006 | D17: =B17*Simulador!C7 -> 1163.1296 | E17: =C17-D17 -> 622.27102 | F17: 2000 | G17: =E17+F17 -> 2622.271 | H17: =B17-G17 -> 177503.36
A18: 17 | B18: =H17 -> 177503.36 | C18: =Simulador!C11 -> 1785.4006 | D18: =B18*Simulador!C7 -> 1146.1968 | E18: =C18-D18 -> 639.20387 | F18: 2000 | G18: =E18+F18 -> 2639.2039 | H18: =B18-G18 -> 174864.16
A19: 18 | B19: =H18 -> 174864.16 | C19: =Simulador!C11 -> 1785.4006 | D19: =B19*Simulador!C7 -> 1129.1546 | E19: =C19-D19 -> 656.24607 | F19: 2000 | G19: =E19+F19 -> 2656.2461 | H19: =B19-G19 -> 172207.91
A20: 19 | B20: =H19 -> 172207.91 | C20: =Simulador!C11 -> 1785.4006 | D20: =B20*Simulador!C7 -> 1112.0023 | E20: =C20-D20 -> 673.39831 | F20: 2000 | G20: =E20+F20 -> 2673.3983 | H20: =B20-G20 -> 169534.51
A21: 20 | B21: =H20 -> 169534.51 | C21: =Simulador!C11 -> 1785.4006 | D21: =B21*Simulador!C7 -> 1094.7393 | E21: =C21-D21 -> 690.66131 | F21: 2000 | G21: =E21+F21 -> 2690.6613 | H21: =B21-G21 -> 166843.85
A22: 21 | B22: =H21 -> 166843.85 | C22: =Simulador!C11 -> 1785.4006 | D22: =B22*Simulador!C7 -> 1077.3649 | E22: =C22-D22 -> 708.03578 | F22: 2000 | G22: =E22+F22 -> 2708.0358 | H22: =B22-G22 -> 164135.82
A23: 22 | B23: =H22 -> 164135.82 | C23: =Simulador!C11 -> 1785.4006 | D23: =B23*Simulador!C7 -> 1059.8782 | E23: =C23-D23 -> 725.52245 | F23: 2000 | G23: =E23+F23 -> 2725.5224 | H23: =B23-G23 -> 161410.3
A24: 23 | B24: =H23 -> 161410.3 | C24: =Simulador!C11 -> 1785.4006 | D24: =B24*Simulador!C7 -> 1042.2786 | E24: =C24-D24 -> 743.12203 | F24: 2000 | G24: =E24+F24 -> 2743.122 | H24: =B24-G24 -> 158667.17
A25: 24 | B25: =H24 -> 158667.17 | C25: =Simulador!C11 -> 1785.4006 | D25: =B25*Simulador!C7 -> 1024.5654 | E25: =C25-D25 -> 760.83526 | F25: 2000 | G25: =E25+F25 -> 2760.8353 | H25: =B25-G25 -> 155906.34
A26: 25 | B26: =H25 -> 155906.34 | C26: =Simulador!C11 -> 1785.4006 | D26: =B26*Simulador!C7 -> 1006.7378 | E26: =C26-D26 -> 778.66287 | F26: 2000 | G26: =E26+F26 -> 2778.6629 | H26: =B26-G26 -> 153127.68
A27: 26 | B27: =H26 -> 153127.68 | C27: =Simulador!C11 -> 1785.4006 | D27: =B27*Simulador!C7 -> 988.79505 | E27: =C27-D27 -> 796.60559 | F27: 2000 | G27: =E27+F27 -> 2796.6056 | H27: =B27-G27 -> 150331.07
A28: 27 | B28: =H27 -> 150331.07 | C28: =Simulador!C11 -> 1785.4006 | D28: =B28*Simulador!C7 -> 970.73646 | E28: =C28-D28 -> 814.66418 | F28: 2000 | G28: =E28+F28 -> 2814.6642 | H28: =B28-G28 -> 147516.41
A29: 28 | B29: =H28 -> 147516.41 | C29: =Simulador!C11 -> 1785.4006 | D29: =B29*Simulador!C7 -> 952.56126 | E29: =C29-D29 -> 832.83938 | F29: 2000 | G29: =E29+F29 -> 2832.8394 | H29: =B29-G29 -> 144683.57
A30: 29 | B30: =H29 -> 144683.57 | C30: =Simulador!C11 -> 1785.4006 | D30: =B30*Simulador!C7 -> 934.2687 | E30: =C30-D30 -> 851.13194 | F30: 2000 | G30: =E30+F30 -> 2851.1319 | H30: =B30-G30 -> 141832.43
A31: 30 | B31: =H30 -> 141832.43 | C31: =Simulador!C11 -> 1785.4006 | D31: =B31*Simulador!C7 -> 915.85801 | E31: =C31-D31 -> 869.54263 | F31: 2000 | G31: =E31+F31 -> 2869.5426 | H31: =B31-G31 -> 138962.89
A32: 31 | B32: =H31 -> 138962.89 | C32: =Simulador!C11 -> 1785.4006 | D32: =B32*Simulador!C7 -> 897.32844 | E32: =C32-D32 -> 888.0722 | F32: 2000 | G32: =E32+F32 -> 2888.0722 | H32: =B32-G32 -> 136074.82
A33: 32 | B33: =H32 -> 136074.82 | C33: =Simulador!C11 -> 1785.4006 | D33: =B33*Simulador!C7 -> 878.67923 | E33: =C33-D33 -> 906.72141 | F33: 2000 | G33: =E33+F33 -> 2906.7214 | H33: =B33-G33 -> 133168.1
A34: 33 | B34: =H33 -> 133168.1 | C34: =Simulador!C11 -> 1785.4006 | D34: =B34*Simulador!C7 -> 859.90958 | E34: =C34-D34 -> 925.49106 | F34: 2000 | G34: =E34+F34 -> 2925.4911 | H34: =B34-G34 -> 130242.61
A35: 34 | B35: =H34 -> 130242.61 | C35: =Simulador!C11 -> 1785.4006 | D35: =B35*Simulador!C7 -> 841.01874 | E35: =C35-D35 -> 944.3819 | F35: 2000 | G35: =E35+F35 -> 2944.3819 | H35: =B35-G35 -> 127298.22
A36: 35 | B36: =H35 -> 127298.22 | C36: =Simulador!C11 -> 1785.4006 | D36: =B36*Simulador!C7 -> 822.00591 | E36: =C36-D36 -> 963.39473 | F36: 2000 | G36: =E36+F36 -> 2963.3947 | H36: =B36-G36 -> 124334.83
A37: 36 | B37: =H36 -> 124334.83 | C37: =Simulador!C11 -> 1785.4006 | D37: =B37*Simulador!C7 -> 802.87031 | E37: =C37-D37 -> 982.53033 | F37: 2000 | G37: =E37+F37 -> 2982.5303 | H37: =B37-G37 -> 121352.3
A38: 37 | B38: =H37 -> 121352.3 | C38: =Simulador!C11 -> 1785.4006 | D38: =B38*Simulador!C7 -> 783.61114 | E38: =C38-D38 -> 1001.7895 | F38: 2000 | G38: =E38+F38 -> 3001.7895 | H38: =B38-G38 -> 118350.51
A39: 38 | B39: =H38 -> 118350.51 | C39: =Simulador!C11 -> 1785.4006 | D39: =B39*Simulador!C7 -> 764.22762 | E39: =C39-D39 -> 1021.173 | F39: 2000 | G39: =E39+F39 -> 3021.173 | H39: =B39-G39 -> 115329.34
A40: 39 | B40: =H39 -> 115329.34 | C40: =Simulador!C11 -> 1785.4006 | D40: =B40*Simulador!C7 -> 744.71892 | E40: =C40-D40 -> 1040.6817 | F40: 2000 | G40: =E40+F40 -> 3040.6817 | H40: =B40-G40 -> 112288.66
...

Sheet Resultados
A1: Plazo Original (meses) | B1: =Simulador!C8 -> 240
A2: Mes de Cancelacion | B2: {=MATCH(TRUE,Amortizacion!H:H<=0,0)-1} -> 73
A3: Meses Reducidos | B3: =B1-B2 -> 167
A5: Simulacion pago rapido
A6: Años | B6: Cuota Necesaria
A7: 3 | B7: =PMT(Simulador!C7,3*12,-Simulador!C5) -> 6790.4819
A8: 4 | B8: =PMT(Simulador!C7,4*12,-Simulador!C5) -> 5284.2006
A9: 6 | B9: =PMT(Simulador!C7,6*12,-Simulador!C5) -> 3786.8567
